<?xml version="1.0" encoding="UTF-8"?>
<testng-results skipped="1" failed="1" ignored="0" total="3" passed="1">
  <reporter-output>
  </reporter-output>
  <suite name="Default suite" duration-ms="84" started-at="2018-05-07T15:06:56Z" finished-at="2018-05-07T15:06:56Z">
    <groups>
    </groups>
    <test name="Default test" duration-ms="84" started-at="2018-05-07T15:06:56Z" finished-at="2018-05-07T15:06:56Z">
      <class name="DependenciesInTestCase.Dependencyintstcases">
        <test-method status="FAIL" signature="startTest()[pri:0, instance:DependenciesInTestCase.Dependencyintstcases@1810399e]" name="startTest" duration-ms="20" started-at="2018-05-07T15:06:56Z" finished-at="2018-05-07T15:06:56Z">
          <exception class="java.lang.AssertionError">
            <message>
              <![CDATA[expected [12] but found [11]]]>
            </message>
            <full-stacktrace>
              <![CDATA[java.lang.AssertionError: expected [12] but found [11]
at org.testng.Assert.fail(Assert.java:96)
at org.testng.Assert.failNotEquals(Assert.java:776)
at org.testng.Assert.assertEqualsImpl(Assert.java:137)
at org.testng.Assert.assertEquals(Assert.java:118)
at org.testng.Assert.assertEquals(Assert.java:652)
at org.testng.Assert.assertEquals(Assert.java:662)
at DependenciesInTestCase.Dependencyintstcases.startTest(Dependencyintstcases.java:12)
at sun.reflect.NativeMethodAccessorImpl.invoke0(Native Method)
at sun.reflect.NativeMethodAccessorImpl.invoke(NativeMethodAccessorImpl.java:62)
at sun.reflect.DelegatingMethodAccessorImpl.invoke(DelegatingMethodAccessorImpl.java:43)
at java.lang.reflect.Method.invoke(Method.java:497)
at org.testng.internal.MethodInvocationHelper.invokeMethod(MethodInvocationHelper.java:124)
at org.testng.internal.Invoker.invokeMethod(Invoker.java:580)
at org.testng.internal.Invoker.invokeTestMethod(Invoker.java:716)
at org.testng.internal.Invoker.invokeTestMethods(Invoker.java:988)
at org.testng.internal.TestMethodWorker.invokeTestMethods(TestMethodWorker.java:125)
at org.testng.internal.TestMethodWorker.run(TestMethodWorker.java:109)
at org.testng.TestRunner.privateRun(TestRunner.java:648)
at org.testng.TestRunner.run(TestRunner.java:505)
at org.testng.SuiteRunner.runTest(SuiteRunner.java:455)
at org.testng.SuiteRunner.runSequentially(SuiteRunner.java:450)
at org.testng.SuiteRunner.privateRun(SuiteRunner.java:415)
at org.testng.SuiteRunner.run(SuiteRunner.java:364)
at org.testng.SuiteRunnerWorker.runSuite(SuiteRunnerWorker.java:52)
at org.testng.SuiteRunnerWorker.run(SuiteRunnerWorker.java:84)
at org.testng.TestNG.runSuitesSequentially(TestNG.java:1208)
at org.testng.TestNG.runSuitesLocally(TestNG.java:1137)
at org.testng.TestNG.runSuites(TestNG.java:1049)
at org.testng.TestNG.run(TestNG.java:1017)
at org.testng.remote.AbstractRemoteTestNG.run(AbstractRemoteTestNG.java:114)
at org.testng.remote.RemoteTestNG.initAndRun(RemoteTestNG.java:251)
at org.testng.remote.RemoteTestNG.main(RemoteTestNG.java:77)
]]>
            </full-stacktrace>
          </exception> <!-- java.lang.AssertionError -->
          <reporter-output>
          </reporter-output>
        </test-method> <!-- startTest -->
        <test-method status="PASS" signature="loggout()[pri:0, instance:DependenciesInTestCase.Dependencyintstcases@1810399e]" name="loggout" duration-ms="7" started-at="2018-05-07T15:06:56Z" finished-at="2018-05-07T15:06:56Z">
          <reporter-output>
          </reporter-output>
        </test-method> <!-- loggout -->
        <test-method status="SKIP" signature="loggin()[pri:0, instance:DependenciesInTestCase.Dependencyintstcases@1810399e]" name="loggin" duration-ms="0" started-at="2018-05-07T15:06:56Z" depends-on-methods="DependenciesInTestCase.Dependencyintstcases.startTest" finished-at="2018-05-07T15:06:56Z">
          <exception class="java.lang.Throwable">
            <message>
              <![CDATA[Method Dependencyintstcases.loggin()[pri:0, instance:DependenciesInTestCase.Dependencyintstcases@1810399e] depends on not successfully finished methods]]>
            </message>
            <full-stacktrace>
              <![CDATA[java.lang.Throwable: Method Dependencyintstcases.loggin()[pri:0, instance:DependenciesInTestCase.Dependencyintstcases@1810399e] depends on not successfully finished methods
at org.testng.internal.Invoker.invokeTestMethods(Invoker.java:887)
at org.testng.internal.TestMethodWorker.invokeTestMethods(TestMethodWorker.java:125)
at org.testng.internal.TestMethodWorker.run(TestMethodWorker.java:109)
at org.testng.TestRunner.privateRun(TestRunner.java:648)
at org.testng.TestRunner.run(TestRunner.java:505)
at org.testng.SuiteRunner.runTest(SuiteRunner.java:455)
at org.testng.SuiteRunner.runSequentially(SuiteRunner.java:450)
at org.testng.SuiteRunner.privateRun(SuiteRunner.java:415)
at org.testng.SuiteRunner.run(SuiteRunner.java:364)
at org.testng.SuiteRunnerWorker.runSuite(SuiteRunnerWorker.java:52)
at org.testng.SuiteRunnerWorker.run(SuiteRunnerWorker.java:84)
at org.testng.TestNG.runSuitesSequentially(TestNG.java:1208)
at org.testng.TestNG.runSuitesLocally(TestNG.java:1137)
at org.testng.TestNG.runSuites(TestNG.java:1049)
at org.testng.TestNG.run(TestNG.java:1017)
at org.testng.remote.AbstractRemoteTestNG.run(AbstractRemoteTestNG.java:114)
at org.testng.remote.RemoteTestNG.initAndRun(RemoteTestNG.java:251)
at org.testng.remote.RemoteTestNG.main(RemoteTestNG.java:77)
]]>
            </full-stacktrace>
          </exception> <!-- java.lang.Throwable -->
          <reporter-output>
          </reporter-output>
        </test-method> <!-- loggin -->
      </class> <!-- DependenciesInTestCase.Dependencyintstcases -->
    </test> <!-- Default test -->
  </suite> <!-- Default suite -->
</testng-results>
